<?xml version="1.0"?>
<!-- =================================================================================== -->
<!-- |    This document was autogenerated by xacro from /opt/ros/melodic/share/pr2_description/robots/pr2.urdf.xacro | -->
<!-- |    EDITING THIS FILE BY HAND IS NOT RECOMMENDED                                 | -->
<!-- =================================================================================== -->
<robot name="pr2" xmlns:xacro="http://www.ros.org/wiki/xacro">
  <!--TODO Define and give source-->
  <!-- ============================   Shoulder   ============================ -->
  <!-- ============================   Upper Arm   ============================ -->
  <!-- ============================   Forearm   ============================ -->
  <!-- DATA SOURCES -->
  <!-- all link offsets, CG, limits are obtained from Function Engineering spreadsheet 090224_link_data.xls unless stated otherwise -->
  <!-- all link geometry sizes are obtained from Function provided CAD model unless stated otherwise -->
  <!-- all simplified collision geometry are hand approximated from CAD model, sometimes from respective bounding boxes -->
  <!-- This is the 'effective' wheel radius. Wheel radius for uncompressed wheel is 0.079.  mp 20080801 -->
  <material name="Blue">
    <color rgba="0.0 0.0 0.8 1.0" />
  </material>
  <material name="Green">
    <color rgba="0.0 0.8 0.0 1.0" />
  </material>
  <material name="Grey">
    <color rgba="0.7 0.7 0.7 1.0" />
  </material>
  <material name="Grey2">
    <color rgba="0.9 0.9 0.9 1.0" />
  </material>
  <material name="Red">
    <color rgba="0.8 0.0 0.0 1.0" />
  </material>
  <material name="White">
    <color rgba="1.0 1.0 1.0 1.0" />
  </material>
  <material name="Black">
    <color rgba="0.1 0.1 0.1 1.0" />
  </material>
  <material name="LightGrey">
    <color rgba="0.6 0.6 0.6 1.0" />
  </material>
  <material name="Caster">
    <texture filename="/opt/ros/melodic/share/pr2_description/materials/textures/pr2_caster_texture.png" />
  </material>
  <material name="Wheel_l">
    <texture filename="/opt/ros/melodic/share/pr2_description/materials/textures/pr2_wheel_left.png" />
  </material>
  <material name="Wheel_r">
    <texture filename="/opt/ros/melodic/share/pr2_description/materials/textures/pr2_wheel_right.png" />
  </material>
  <material name="RollLinks">
    <texture filename="/opt/ros/melodic/share/pr2_description/materials/textures/pr2_wheel_left.png" />
  </material>
  <!-- Now we can start using the macros included above to define the actual PR2 -->
  <link name="base_link">
    <collision>
      <origin rpy="0 0 0" xyz="0 0 0" />
      <geometry>
        <mesh filename="meshes/base_L.obj" />
      </geometry>
    </collision>
  </link>
  <!-- Changed the below to fixed -->
  <joint name="torso_lift_joint" type="fixed">
    <axis xyz="0 0 1" />
    <limit effort="10000" lower="0.0" upper="0.33"
    velocity="0.013" />
    <!-- alpha tested velocity and effort limits -->
    <safety_controller k_position="100" k_velocity="2000000"
    soft_lower_limit="0.0115" soft_upper_limit="0.325" />
    <calibration falling="0.00475" />
    <dynamics damping="20000.0" />
    <origin rpy="0 0 0" xyz="-0.05 0 0.859675" />
    <parent link="base_link" />
    <child link="torso_lift_link" />
  </joint>
  <link name="torso_lift_link">
    <collision name="torso_lift_collision">
      <origin rpy="0 0 0" xyz="0 0 0" />
      <geometry>
        <mesh filename="meshes/torso_lift_L.obj" />
      </geometry>
    </collision>
  </link>
  <!-- Head -->
  <joint name="head_pan_joint" type="fixed">
    <axis xyz="0 0 1"/>
    <limit effort="2.645" lower="-3.007" upper="3.007" velocity="6"/>
    <!-- alpha tested velocity and effort limits -->
    <safety_controller k_position="100" k_velocity="1.5" soft_lower_limit="-2.857" soft_upper_limit="2.857"/>
    <calibration rising="0.0"/>
    <dynamics damping="0.5"/>
    <origin rpy="0.0 0.0 0.0" xyz="0.0 0.0 0.38145"/>
    <parent link="torso_lift_link"/>
    <child link="head_pan_link"/>
  </joint>
  <link name="head_pan_link">
    <collision>
      <geometry>
        <mesh filename="meshes/head_pan_L.obj"/>
      </geometry>
    </collision>
  </link>
  <joint name="head_tilt_joint" type="fixed">
    <axis xyz="0 1 0"/>
    <limit effort="18" lower="-0.471238" upper="1.39626" velocity="5"/>
    <!-- alpha tested velocity and effort limits -->
    <safety_controller k_position="100" k_velocity="3.0" soft_lower_limit="-0.3712" soft_upper_limit="1.29626"/>
    <calibration falling="0.0"/>
    <dynamics damping="10.0"/>
    <origin rpy="0 0 0" xyz="0.0 0 0.03"/>
    <parent link="head_pan_link"/>
    <child link="head_tilt_link"/>
  </joint>
  <link name="head_tilt_link">
    <collision>
      <origin rpy="0.0 0.0 0.0" xyz="0 0 0"/>
      <geometry>
        <mesh filename="meshes/head_tilt_L.obj"/>
      </geometry>
    </collision>
  </link>
  <joint name="head_plate_frame_joint" type="fixed">
    <origin rpy="0 0 0" xyz="0.0232 0 0.0645"/>
    <parent link="head_tilt_link"/>
    <child link="sensor_mount_link"/>
  </joint>
  <link name="sensor_mount_link"/> 
  <joint name="laser_tilt_mount_joint" type="fixed">
    <axis xyz="0 1 0"/>
    <limit effort="0.65" lower="-0.7854" upper="1.48353" velocity="10.0"/>
    <!-- alpha tested velocity and effort limits -->
    <safety_controller k_position="100" k_velocity="0.05" soft_lower_limit="-0.7353999999999999" soft_upper_limit="1.43353"/>
    <calibration falling="0.0"/>
    <dynamics damping="0.008"/>
    <origin rpy="0 0 0" xyz="0.09893 0 0.227"/>
    <parent link="torso_lift_link"/>
    <child link="laser_tilt_mount_link"/>
  </joint>
  <link name="laser_tilt_mount_link">
    <collision>
      <origin rpy="0 0 0" xyz="0 0 0"/>
      <geometry>
        <mesh filename="meshes/tilting_hokuyo_L.obj"/>
      </geometry>
    </collision>
  </link>
  <joint name="laser_tilt_joint" type="fixed">
    <axis xyz="0 1 0"/>
    <origin rpy="0 0 0" xyz="0 0 0.03"/>
    <parent link="laser_tilt_mount_link"/>
    <child link="laser_tilt_link"/>
  </joint>
  <link name="laser_tilt_link" type="laser"/>
  <!-- Shoulder pan -->
  <joint name="r_shoulder_pan_joint" type="revolute">
    <axis xyz="0 0 1" />
    <origin rpy="0 0 0" xyz="0.0 -0.188 0.0" />
    <!-- transform from parent link to this joint frame -->
    <parent link="torso_lift_link" />
    <child link="r_shoulder_pan_link" />
    <limit effort="30" lower="-2.2853981633974483"
    upper="0.7146018366025517" velocity="2.088" />
    <!-- alpha tested velocity and effort limits -->
    <dynamics damping="10.0" />
    <safety_controller k_position="100" k_velocity="10"
    soft_lower_limit="-2.1353981633974484"
    soft_upper_limit="0.5646018366025517" />
    <!-- joint angle when the rising or the falling flag is activated on PR2 -->
    <calibration rising="-0.7853981633974483" />
  </joint>
  <link name="r_shoulder_pan_link">
    <collision>
      <origin rpy="0 0 0" xyz="0.0 0 0.0" />
      <geometry>
        <mesh filename="meshes/shoulder_pan.obj" />
      </geometry>
    </collision>
  </link>
  <!-- Shoulder lift -->
  <joint name="r_shoulder_lift_joint" type="revolute">
    <axis xyz="0 1 0" />
    <!-- Limits updated from Function's CAD values as of 2009_02_24 (link_data.xls) -->
    <limit effort="30" lower="-0.5236" upper="1.3963"
    velocity="2.082" />
    <!-- alpha tested velocity and effort limits -->
    <safety_controller k_position="100" k_velocity="10"
    soft_lower_limit="-0.3535999999999999"
    soft_upper_limit="1.2963" />
    <calibration falling="0.0" />
    <dynamics damping="10.0" />
    <origin rpy="0 0 0" xyz="0.1 0 0" />
    <parent link="r_shoulder_pan_link" />
    <child link="r_shoulder_lift_link" />
  </joint>
  <link name="r_shoulder_lift_link">
    <collision>
      <origin rpy="0 0 0" xyz="0 0 0" />
      <geometry>
        <mesh filename="meshes/shoulder_lift.obj" />
      </geometry>
    </collision>
  </link>
  <joint name="r_upper_arm_roll_joint" type="revolute">
    <axis xyz="1 0 0" />
    <origin rpy="0 0 0" xyz="0 0 0" />
    <parent link="r_shoulder_lift_link" />
    <child link="r_upper_arm_roll_link" />
    <limit effort="30" lower="-3.9000000000000004" upper="0.8"
    velocity="3.27" />
    <!-- alpha tested velocity and effort limits -->
    <safety_controller k_position="100" k_velocity="2"
    soft_lower_limit="-3.7500000000000004"
    soft_upper_limit="0.65" />
    <calibration rising="-1.5707963267948966" />
    <dynamics damping="0.1" />
  </joint>
  <link name="r_upper_arm_roll_link">
    <collision>
      <origin rpy="0 0 0" xyz="0 0 0" />
      <geometry>
        <mesh filename="meshes/upper_arm_roll_L.obj" />
      </geometry>
    </collision>
  </link>
  <joint name="r_upper_arm_joint" type="fixed">
    <origin rpy="0 0 0" xyz="0 0 0" />
    <parent link="r_upper_arm_roll_link" />
    <child link="r_upper_arm_link" />
  </joint>
  <link name="r_upper_arm_link">
    <collision>
      <origin rpy="0 0 0" xyz="0 0 0" />
      <geometry>
        <mesh filename="meshes/upper_arm.obj" />
      </geometry>
    </collision>
  </link>
  <!-- Has upperarm link -->
  <!-- No transmission, since this a fixed joint w/o actuator -->
  <!-- forearm_roll_link is a fictitious link internal to elbow_flex_link, provides an attachment point for the actual forearm -->
  <joint name="r_forearm_roll_joint" type="continuous">
    <axis xyz="1 0 0" />
    <limit effort="30" velocity="3.5999999999999996" />
    <!-- alpha tested velocity and effort limits -->
    <safety_controller k_velocity="1" />
    <calibration rising="0.0" />
    <dynamics damping="0.1" />
    <origin rpy="0 0 0" xyz="0 0 0" />
    <parent link="r_elbow_flex_link" />
    <child link="r_forearm_roll_link" />
  </joint>
  <!-- TODO: inertial tag should be optional -->
  <link name="r_forearm_roll_link">
    <!-- TODO: collision tag should be optional -->
    <collision>
      <origin rpy="0 0 0" xyz="0 0 0" />
      <geometry>
        <mesh filename="meshes/forearm_roll_L.obj" />
      </geometry>
    </collision>
  </link>
  <!-- Elbow flex -->
  <joint name="r_elbow_flex_joint" type="revolute">
    <axis xyz="0 1 0" />
    <!-- Note: Overtravel limits are 140, -7 degrees instead of 133, 0 -->
    <limit effort="30" lower="-2.3213" upper="0.00"
    velocity="3.3" />
    <!-- alpha tested velocity and effort limits -->
    <safety_controller k_position="100" k_velocity="3"
    soft_lower_limit="-2.1212999999999997"
    soft_upper_limit="-0.15" />
    <calibration falling="-1.1606" />
    <dynamics damping="1.0" />
    <origin rpy="0 0 0" xyz="0.4 0 0" />
    <parent link="r_upper_arm_link" />
    <child link="r_elbow_flex_link" />
  </joint>
  <link name="r_elbow_flex_link">
    <collision>
      <origin rpy="0 0 0" xyz="0 0 0" />
      <geometry>
        <mesh filename="meshes/elbow_flex.obj" />
      </geometry>
    </collision>
  </link>
  <joint name="r_forearm_joint" type="fixed">
    <origin rpy="0 0 0" xyz="0 0 0" />
    <!-- transform from parent link to this joint frame -->
    <parent link="r_forearm_roll_link" />
    <child link="r_forearm_link" />
  </joint>
  <link name="r_forearm_link">
    <collision>
      <origin rpy="0 0 0" xyz="0 0 0" />
      <geometry>
        <mesh filename="meshes/forearm.obj" />
      </geometry>
    </collision>
  </link>
  <!-- Wrist flex -->
  <joint name="r_wrist_flex_joint" type="revolute">
    <axis xyz="0 1 0" />
    <limit effort="10" lower="-2.18" upper="0.0"
    velocity="3.078" />
    <!-- alpha tested velocity and effort limits -->
    <safety_controller k_position="20" k_velocity="4"
    soft_lower_limit="-2.0" soft_upper_limit="-0.1" />
    <dynamics damping="0.1" />
    <calibration falling="-0.5410521" />
    <origin rpy="0 0 0" xyz="0.321 0 0" />
    <parent link="r_forearm_link" />
    <child link="r_wrist_flex_link" />
  </joint>
  <link name="r_wrist_flex_link">
    <collision>
      <origin rpy="0 0 0" xyz="0 0 0" />
      <geometry>
        <mesh filename="meshes/wrist_flex.obj" />
      </geometry>
    </collision>
  </link>
  <!-- Wrist roll -->
  <joint name="r_wrist_roll_joint" type="continuous">
    <axis xyz="1 0 0" />
    <limit effort="10" velocity="3.5999999999999996" />
    <!-- alpha tested velocity and effort limits -->
    <safety_controller k_velocity="2" />
    <dynamics damping="0.1" />
    <calibration rising="-1.5707963267948966" />
    <origin rpy="0 0 0" xyz="0 0 0" />
    <parent link="r_wrist_flex_link" />
    <child link="r_wrist_roll_link" />
  </joint>
  <link name="r_wrist_roll_link">
    <collision>
      <origin rpy="0 0 0" xyz="0 0 0" />
      <geometry>
        <mesh filename="meshes/wrist_roll_L.obj" />
      </geometry>
    </collision>
  </link>
  <joint name="r_gripper_palm_joint" type="fixed">
    <origin rpy="0 0 0" xyz="0 0 0" />
    <parent link="r_wrist_roll_link" />
    <child link="r_gripper_palm_link" />
  </joint>
  <link name="r_gripper_palm_link">
    <collision>
      <origin rpy="0 0 0" xyz="0 0 0" />
      <geometry>
        <mesh filename="meshes/gripper_palm.obj" />
      </geometry>
    </collision>
  </link>
  <joint name="r_gripper_tool_joint" type="fixed">
    <origin rpy="0 0 0" xyz="0.18 0 0" />
    <parent link="r_gripper_palm_link" />
    <child link="rgrippertoolframe" />
  </joint>
  <link name="rgrippertoolframe" />
  <!-- actuated motor screw joint -->
  <!-- Finger proximal digit -->
  <joint name="r_gripper_l_finger_joint" type="fixed">
    <axis xyz="0 0 1" />
    <!-- limits on passive finger and finger top joints without
    transmission are not enforced by safety controllers.
    The lower/upper limits and are enforced in PR2 simulation and
    effort and velocity limits are ignored. This is also needed because
    these joints are declared revolute rather than continuous.-->
    <limit effort="1000.0" lower="0.0" upper="0.548"
    velocity="0.5" />
    <dynamics damping="0.02" />
    <origin rpy="0 0 0" xyz="0.07691 0.01 0" />
    <parent link="r_gripper_palm_link" />
    <child link="r_gripper_l_finger_link" />
  </joint>
  <link name="r_gripper_l_finger_link">
    <collision>
      <origin rpy="0 0 0" xyz="0 0 0" />
      <geometry>
        <mesh filename="meshes/l_finger.obj" />
      </geometry>
    </collision>
  </link>
  <!-- Finger proximal digit -->
  <joint name="r_gripper_r_finger_joint" type="fixed">
    <axis xyz="0 0 -1" />
    <origin rpy="0 0 0" xyz="0.07691 -0.01 0" />
    <!-- limits on passive finger and finger top joints without
    transmission are not enforced by safety controllers.
    The lower/upper limits and are enforced in PR2 simulation and
    effort and velocity limits are ignored. This is also needed because
    these joints are declared revolute rather than continuous.-->
    <limit effort="1000.0" lower="0.0" upper="0.548"
    velocity="0.5" />
    <dynamics damping="0.02" />
    <mimic joint="r_gripper_l_finger_joint" multiplier="1"
    offset="0" />
    <parent link="r_gripper_palm_link" />
    <child link="r_gripper_r_finger_link" />
  </joint>
  <link name="r_gripper_r_finger_link">
    <collision>
      <origin rpy="3.141592653589793 0 0" xyz="0 0 0" />
      <geometry>
        <mesh filename="meshes/l_finger.obj" />
      </geometry>
    </collision>
  </link>
  <!-- Finger tip -->
  <joint name="r_gripper_l_finger_tip_joint" type="fixed">
    <axis xyz="0 0 -1" />
    <origin rpy="0 0 0" xyz="0.09137 0.00495 0" />
    <!-- limits on passive finger and finger top joints without
    transmission are not enforced by safety controllers.
    The lower/upper limits and are enforced in PR2 simulation and
    effort and velocity limits are ignored. This is also needed because
    these joints are declared revolute rather than continuous.-->
    <limit effort="1000.0" lower="0.0" upper="0.548"
    velocity="0.5" />
    <dynamics damping="0.001" />
    <mimic joint="r_gripper_l_finger_joint" multiplier="1"
    offset="0" />
    <parent link="r_gripper_l_finger_link" />
    <child link="r_gripper_l_finger_tip_link" />
  </joint>
  <link name="r_gripper_l_finger_tip_link">
    <collision>
      <origin rpy="0 0 0" xyz="0 0 0" />
      <geometry>
        <mesh filename="meshes/l_finger_tip.obj" />
      </geometry>
    </collision>
  </link>
  <!-- Finger tip -->
  <joint name="r_gripper_r_finger_tip_joint" type="fixed">
    <axis xyz="0 0 1" />
    <origin rpy="0 0 0" xyz="0.09137 -0.00495 0" />
    <!-- limits on passive finger and finger top joints without
    transmission are not enforced by safety controllers.
    The lower/upper limits and are enforced in PR2 simulation and
    effort and velocity limits are ignored. This is also needed because
    these joints are declared revolute rather than continuous.-->
    <limit effort="1000.0" lower="0.0" upper="0.548"
    velocity="0.5" />
    <dynamics damping="0.001" />
    <mimic joint="r_gripper_l_finger_joint" multiplier="1"
    offset="0" />
    <parent link="r_gripper_r_finger_link" />
    <child link="r_gripper_r_finger_tip_link" />
  </joint>
  <link name="r_gripper_r_finger_tip_link">
    <collision>
      <origin rpy="3.141592653589793 0 0" xyz="0 0 0" />
      <geometry>
        <mesh filename="meshes/l_finger_tip.obj" />
      </geometry>
    </collision>
  </link>
  <!-- Finger proximal digit -->
  <!-- fictitous joint that represents the gripper gap -->
  <!-- effort is the linear force at the gripper gap
  velocity limit is the linear velocity limit at the gripper gap
  try and introduce a very stiff spring
  The velocity limits are alpha tested.
  The effort limits are somewhat inflated.
  k_velocity was recently raised from 500.0 to 5000.0.  Tested on beta
  -->
  <joint name="r_gripper_joint" type="fixed">
    <parent link="r_gripper_r_finger_tip_link" />
    <child link="r_gripper_l_finger_tip_frame" />
    <axis xyz="0 1 0" />
    <dynamics damping="10.0" />
    <limit effort="1000.0" lower="0.0" upper="0.09"
    velocity="0.2" />
    <safety_controller k_position="20.0" k_velocity="5000.0"
    soft_lower_limit="-0.01" soft_upper_limit="0.088" />
  </joint>
  <!-- This link is the same as the l_finger_tip_link,
  but because the urdf does not support graph structures,
  this link exists twice -->
  <link name="r_gripper_l_finger_tip_frame" />
  <!-- Shoulder pan -->
  <joint name="l_shoulder_pan_joint" type="revolute">
    <axis xyz="0 0 1" />
    <origin rpy="0 0 0" xyz="0.0 0.188 0.0" />
    <!-- transform from parent link to this joint frame -->
    <parent link="torso_lift_link" />
    <child link="l_shoulder_pan_link" />
    <limit effort="30" lower="-0.7146018366025517"
    upper="2.2853981633974483" velocity="2.088" />
    <!-- alpha tested velocity and effort limits -->
    <dynamics damping="10.0" />
    <safety_controller k_position="100" k_velocity="10"
    soft_lower_limit="-0.5646018366025517"
    soft_upper_limit="2.1353981633974484" />
    <!-- joint angle when the rising or the falling flag is activated on PR2 -->
    <calibration rising="0.7853981633974483" />
  </joint>
  <link name="l_shoulder_pan_link">
    <collision>
      <origin rpy="0 0 0" xyz="0.0 0 0.0" />
      <geometry>
        <mesh filename="meshes/shoulder_pan.obj" />
      </geometry>
    </collision>
  </link>
  <!-- Shoulder lift -->
  <joint name="l_shoulder_lift_joint" type="revolute">
    <axis xyz="0 1 0" />
    <!-- Limits updated from Function's CAD values as of 2009_02_24 (link_data.xls) -->
    <limit effort="30" lower="-0.5236" upper="1.3963"
    velocity="2.082" />
    <!-- alpha tested velocity and effort limits -->
    <safety_controller k_position="100" k_velocity="10"
    soft_lower_limit="-0.3535999999999999"
    soft_upper_limit="1.2963" />
    <calibration falling="0.0" />
    <dynamics damping="10.0" />
    <origin rpy="0 0 0" xyz="0.1 0 0" />
    <parent link="l_shoulder_pan_link" />
    <child link="l_shoulder_lift_link" />
  </joint>
  <link name="l_shoulder_lift_link">
    <collision>
      <origin rpy="0 0 0" xyz="0 0 0" />
      <geometry>
        <mesh filename="meshes/shoulder_lift.obj" />
      </geometry>
    </collision>
  </link>
  <joint name="l_upper_arm_roll_joint" type="revolute">
    <axis xyz="1 0 0" />
    <origin rpy="0 0 0" xyz="0 0 0" />
    <parent link="l_shoulder_lift_link" />
    <child link="l_upper_arm_roll_link" />
    <limit effort="30" lower="-0.8" upper="3.9000000000000004"
    velocity="3.27" />
    <!-- alpha tested velocity and effort limits -->
    <safety_controller k_position="100" k_velocity="2"
    soft_lower_limit="-0.65"
    soft_upper_limit="3.7500000000000004" />
    <calibration rising="1.5707963267948966" />
    <dynamics damping="0.1" />
  </joint>
  <link name="l_upper_arm_roll_link">
    <collision>
      <origin rpy="0 0 0" xyz="0 0 0" />
      <geometry>
        <mesh filename="meshes/upper_arm_roll_L.obj" />
      </geometry>
    </collision>
  </link>
  <joint name="l_upper_arm_joint" type="fixed">
    <origin rpy="0 0 0" xyz="0 0 0" />
    <parent link="l_upper_arm_roll_link" />
    <child link="l_upper_arm_link" />
  </joint>
  <link name="l_upper_arm_link">
    <collision>
      <origin rpy="0 0 0" xyz="0 0 0" />
      <geometry>
        <mesh filename="meshes/upper_arm.obj" />
      </geometry>
    </collision>
  </link>
  <!-- Has upperarm link -->
  <!-- No transmission, since this a fixed joint w/o actuator -->
  <!-- forearm_roll_link is a fictitious link internal to elbow_flex_link, provides an attachment point for the actual forearm -->
  <joint name="l_forearm_roll_joint" type="continuous">
    <axis xyz="1 0 0" />
    <limit effort="30" velocity="3.5999999999999996" />
    <!-- alpha tested velocity and effort limits -->
    <safety_controller k_velocity="1" />
    <calibration rising="0.0" />
    <dynamics damping="0.1" />
    <origin rpy="0 0 0" xyz="0 0 0" />
    <parent link="l_elbow_flex_link" />
    <child link="l_forearm_roll_link" />
  </joint>
  <!-- TODO: inertial tag should be optional -->
  <link name="l_forearm_roll_link">
    <!-- TODO: collision tag should be optional -->
    <collision>
      <origin rpy="0 0 0" xyz="0 0 0" />
      <geometry>
        <mesh filename="meshes/forearm_roll_L.obj" />
      </geometry>
    </collision>
  </link>
  <!-- Elbow flex -->
  <joint name="l_elbow_flex_joint" type="revolute">
    <axis xyz="0 1 0" />
    <!-- Note: Overtravel limits are 140, -7 degrees instead of 133, 0 -->
    <limit effort="30" lower="-2.3213" upper="0.00"
    velocity="3.3" />
    <!-- alpha tested velocity and effort limits -->
    <safety_controller k_position="100" k_velocity="3"
    soft_lower_limit="-2.1212999999999997"
    soft_upper_limit="-0.15" />
    <calibration falling="-1.1606" />
    <dynamics damping="1.0" />
    <origin rpy="0 0 0" xyz="0.4 0 0" />
    <parent link="l_upper_arm_link" />
    <child link="l_elbow_flex_link" />
  </joint>
  <link name="l_elbow_flex_link">
    <collision>
      <origin rpy="0 0 0" xyz="0 0 0" />
      <geometry>
        <mesh filename="meshes/elbow_flex.obj" />
      </geometry>
    </collision>
  </link>
  <joint name="l_forearm_joint" type="fixed">
    <origin rpy="0 0 0" xyz="0 0 0" />
    <!-- transform from parent link to this joint frame -->
    <parent link="l_forearm_roll_link" />
    <child link="l_forearm_link" />
  </joint>
  <link name="l_forearm_link">
    <collision>
      <origin rpy="0 0 0" xyz="0 0 0" />
      <geometry>
        <mesh filename="meshes/forearm.obj" />
      </geometry>
    </collision>
  </link>
  <!-- Wrist flex -->
  <joint name="l_wrist_flex_joint" type="revolute">
    <axis xyz="0 1 0" />
    <limit effort="10" lower="-2.18" upper="0.0"
    velocity="3.078" />
    <!-- alpha tested velocity and effort limits -->
    <safety_controller k_position="20" k_velocity="4"
    soft_lower_limit="-2.0" soft_upper_limit="-0.1" />
    <dynamics damping="0.1" />
    <calibration falling="-0.5410521" />
    <origin rpy="0 0 0" xyz="0.321 0 0" />
    <parent link="l_forearm_link" />
    <child link="l_wrist_flex_link" />
  </joint>
  <link name="l_wrist_flex_link">
    <collision>
      <origin rpy="0 0 0" xyz="0 0 0" />
      <geometry>
        <mesh filename="meshes/wrist_flex.obj" />
      </geometry>
    </collision>
  </link>
  <!-- Wrist roll -->
  <joint name="l_wrist_roll_joint" type="continuous">
    <axis xyz="1 0 0" />
    <limit effort="10" velocity="3.5999999999999996" />
    <!-- alpha tested velocity and effort limits -->
    <safety_controller k_velocity="2" />
    <dynamics damping="0.1" />
    <calibration rising="-1.5707963267948966" />
    <origin rpy="0 0 0" xyz="0 0 0" />
    <parent link="l_wrist_flex_link" />
    <child link="l_wrist_roll_link" />
  </joint>
  <link name="l_wrist_roll_link">
    <collision>
      <origin rpy="0 0 0" xyz="0 0 0" />
      <geometry>
        <mesh filename="meshes/wrist_roll_L.obj" />
      </geometry>
    </collision>
  </link>
  <joint name="l_gripper_palm_joint" type="fixed">
    <origin rpy="0 0 0" xyz="0 0 0" />
    <parent link="l_wrist_roll_link" />
    <child link="l_gripper_palm_link" />
  </joint>
  <link name="l_gripper_palm_link">
    <collision>
      <origin rpy="0 0 0" xyz="0 0 0" />
      <geometry>
        <mesh filename="meshes/gripper_palm.obj" />
      </geometry>
    </collision>
  </link>
  <joint name="l_gripper_tool_joint" type="fixed">
    <origin rpy="0 0 0" xyz="0.18 0 0" />
    <parent link="l_gripper_palm_link" />
    <child link="lgrippertoolframe" />
  </joint>
  <link name="lgrippertoolframe" />
  <!-- Finger proximal digit -->
  <joint name="l_gripper_l_finger_joint" type="fixed">
    <axis xyz="0 0 1" />
    <!-- limits on passive finger and finger top joints without
    transmission are not enforced by safety controllers.
    The lower/upper limits and are enforced in PR2 simulation and
    effort and velocity limits are ignored. This is also needed because
    these joints are declared revolute rather than continuous.-->
    <limit effort="1000.0" lower="0.0" upper="0.548"
    velocity="0.5" />
    <dynamics damping="0.02" />
    <origin rpy="0 0 0" xyz="0.07691 0.01 0" />
    <parent link="l_gripper_palm_link" />
    <child link="l_gripper_l_finger_link" />
  </joint>
  <link name="l_gripper_l_finger_link">
    <collision>
      <origin rpy="0 0 0" xyz="0 0 0" />
      <geometry>
        <mesh filename="meshes/l_finger.obj" />
      </geometry>
    </collision>
  </link>
  <!-- Finger proximal digit -->
  <joint name="l_gripper_r_finger_joint" type="fixed">
    <axis xyz="0 0 -1" />
    <origin rpy="0 0 0" xyz="0.07691 -0.01 0" />
    <!-- limits on passive finger and finger top joints without
    transmission are not enforced by safety controllers.
    The lower/upper limits and are enforced in PR2 simulation and
    effort and velocity limits are ignored. This is also needed because
    these joints are declared revolute rather than continuous.-->
    <limit effort="1000.0" lower="0.0" upper="0.548"
    velocity="0.5" />
    <dynamics damping="0.02" />
    <mimic joint="l_gripper_l_finger_joint" multiplier="1"
    offset="0" />
    <parent link="l_gripper_palm_link" />
    <child link="l_gripper_r_finger_link" />
  </joint>
  <link name="l_gripper_r_finger_link">
    <collision>
      <origin rpy="3.141592653589793 0 0" xyz="0 0 0" />
      <geometry>
        <mesh filename="meshes/l_finger.obj" />
      </geometry>
    </collision>
  </link>
  <!-- Finger tip -->
  <joint name="l_gripper_l_finger_tip_joint" type="fixed">
    <axis xyz="0 0 -1" />
    <origin rpy="0 0 0" xyz="0.09137 0.00495 0" />
    <!-- limits on passive finger and finger top joints without
    transmission are not enforced by safety controllers.
    The lower/upper limits and are enforced in PR2 simulation and
    effort and velocity limits are ignored. This is also needed because
    these joints are declared revolute rather than continuous.-->
    <limit effort="1000.0" lower="0.0" upper="0.548"
    velocity="0.5" />
    <dynamics damping="0.001" />
    <mimic joint="l_gripper_l_finger_joint" multiplier="1"
    offset="0" />
    <parent link="l_gripper_l_finger_link" />
    <child link="l_gripper_l_finger_tip_link" />
  </joint>
  <link name="l_gripper_l_finger_tip_link">
    <collision>
      <origin rpy="0 0 0" xyz="0 0 0" />
      <geometry>
        <mesh filename="meshes/l_finger_tip.obj" />
      </geometry>
    </collision>
  </link>
  <!-- Finger tip -->
  <joint name="l_gripper_r_finger_tip_joint" type="fixed">
    <axis xyz="0 0 1" />
    <origin rpy="0 0 0" xyz="0.09137 -0.00495 0" />
    <!-- limits on passive finger and finger top joints without
    transmission are not enforced by safety controllers.
    The lower/upper limits and are enforced in PR2 simulation and
    effort and velocity limits are ignored. This is also needed because
    these joints are declared revolute rather than continuous.-->
    <limit effort="1000.0" lower="0.0" upper="0.548"
    velocity="0.5" />
    <dynamics damping="0.001" />
    <mimic joint="l_gripper_l_finger_joint" multiplier="1"
    offset="0" />
    <parent link="l_gripper_r_finger_link" />
    <child link="l_gripper_r_finger_tip_link" />
  </joint>
  <link name="l_gripper_r_finger_tip_link">
    <collision>
      <origin rpy="3.141592653589793 0 0" xyz="0 0 0" />
      <geometry>
        <mesh filename="meshes/l_finger_tip.obj" />
      </geometry>
    </collision>
  </link>
  <!-- fictitous joint that represents the gripper gap -->
  <!-- effort is the linear force at the gripper gap
  velocity limit is the linear velocity limit at the gripper gap
  try and introduce a very stiff spring
  The velocity limits are alpha tested.
  The effort limits are somewhat inflated.
  k_velocity was recently raised from 500.0 to 5000.0.  Tested on beta
  -->
  <joint name="l_gripper_joint" type="fixed">
    <parent link="l_gripper_r_finger_tip_link" />
    <child link="l_gripper_l_finger_tip_frame" />
    <axis xyz="0 1 0" />
    <dynamics damping="10.0" />
    <limit effort="1000.0" lower="0.0" upper="0.09"
    velocity="0.2" />
    <safety_controller k_position="20.0" k_velocity="5000.0"
    soft_lower_limit="-0.01" soft_upper_limit="0.088" />
  </joint>
  <!-- This link is the same as the l_finger_tip_link,
  but because the urdf does not support graph structures,
  this link exists twice -->
  <link name="l_gripper_l_finger_tip_frame" />
</robot>
